Workbook

Sheet サマリ
B1: EC業務ナレッジ チャットボット 月額コスト試算 サマリ
B2: 単価: 2026年2月時点 Azure OpenAI 料金 ／ ※数値は「計算」シートから参照
B4: コスト区分 | C4: 現状（30名） | D4: 6万円（150名） | E4: 300名 | F4: 備考
B5: ① ナレッジ更新 [円/月] | C5: =計算!C28 | D5: =計算!D28 | E5: =計算!E28 | F5: 更新頻度・資料数が同じなら全シナリオ共通
B6: ② インフラ [円/月] | C6: =計算!C38 | D6: =計算!D38 | E6: =計算!E38 | F6: 300名はAI Search Standard化で大幅増
B7: ③ Chatbot回答 [円/月] | C7: =計算!C48 | D7: =計算!D48 | E7: =計算!E48 | F7: 利用者数×質問数にほぼ比例
B8: 月額合計 [円] | C8: =計算!C57 | D8: =計算!D57 | E8: =計算!E57
B9: 年額概算 [円] | C9: =計算!C58 | D9: =計算!D58 | E9: =計算!E58
B11: ■ 注意事項
B12: ・コスト増の主要因: 300名では Azure AI Search を Basic→Standard S0 へ変更が必要（Basic $73→Standard S0 $250）
B13: ・ナレッジ更新コストは更新対象ファイル数が変わらなければ利用者数に関係なく一定
B14: ・Chatbot回答コストは利用者数・質問数に比例して増加（1QA単価は常に¥0.378）
B15: ・黄色セル（利用者数・1日あたり質問数）の値を変更すると全コストが自動再計算されます

Sheet 単価表
B1: 単価表・参照データ（2026年2月時点）
B3: ■ AIモデル単価
B4: モデル名 | C4: Input ($/1Mトークン) | D4: Output ($/1Mトークン)
B5: gpt-5-mini | C5: 0.25 | D5: 2
B6: gpt-5.1 | C6: 1.25 | D6: 10
B7: text-embedding-3-large | C7: 0.13 | D7: —
B9: ■ Azure 固定費（月額）
B10: リソース | C10: Basic 月額(USD) | D10: Standard 月額(USD) | E10: プラン備考
B11: Azure AI Search | C11: 73 | D11: 250 | E11: Basic / Standard S0
B12: App Service Plan | C12: 13 | D12: 100 | E12: B1 / S2
B13: Azure SQL Database | C13: 4.9 | D13: 75 | E13: Basic 5DTU / S2
B15: ■ Knowledge Maker 処理パラメータ
B16: パラメータ | C16: 値 | D16: 備考
B17: 1画像あたり Input トークン | C17: 1500 | D17: Vision API prompt + image
B18: 1画像あたり Output トークン | C18: 500 | D18: 画像説明テキスト
B19: 日本語 文字→トークン 変換係数 | C19: 0.5 | D19: 1文字 ≒ 0.5トークン
B20: Step2 テンプレートトークン | C20: 2000 | D20: フォーマット指示
B21: Step3 構造提案 Input トークン | C21: 10000 | D21: 全資料要約を含む
B22: Step3 構造提案 Output トークン | C22: 8000 | D22: フォルダ構造JSON
B23: Step3 要約 Input トークン/ファイル | C23: 2000
B24: Step3 要約 Output トークン/ファイル | C24: 2000
B25: ■ Chat 処理パラメータ
B26: パラメータ | C26: 値 | D26: 備考
B27: 1質問あたり Input トークン | C27: 4000 | D27: システムプロンプト + 検索結果20件
B28: 1質問あたり Output トークン | C28: 500 | D28: 回答テキスト
B29: Embedding クエリトークン/質問 | C29: 100 | D29: 質問文のベクトル化

Sheet 計算
B1: EC業務ナレッジ チャットボット 月額コスト試算
B2: ※ 黄色セルの数値を変更すると自動再計算されます
B3: 項目 | C3: 現状（30名） | D3: 6万円（150名） | E3: 300名 | F3: 単位
B5: ■ 主要変数
B6: 項目 | C6: 現状（30名） | D6: 6万円（150名） | E6: 300名 | F6: 単位
B7: ナレッジ更新回数/月 | C7: 4 | D7: 4 | E7: 4 | F7: 回/月
B8: 1回あたり処理資料数 | C8: 4 | D8: 4 | E8: 4 | F8: 件
B9: 1資料あたり平均文字数 | C9: 350000 | D9: 350000 | E9: 350000 | F9: 字
B10: 1資料あたり平均画像数 | C10: 250 | D10: 250 | E10: 250 | F10: 枚
B11: 1日あたりチャット質問数 | C11: 20 | D11: 25 | E11: 25 | F11: 件/日
B12: 利用者数 | C12: 30 | D12: 150 | E12: 300 | F12: 人
B13: 月間営業日 | C13: 22 | D13: 22 | E13: 22 | F13: 日
B14: Agent平均検索ラウンド数 | C14: 1.5 | D14: 1.5 | E14: 1.5 | F14: 回
B15: 為替レート (USD→JPY) | C15: 150 | D15: 150 | E15: 150 | F15: 円/USD
B18: ① ナレッジ更新コスト（Knowledge Maker API費用）
B19: 項目 | C19: 現状（30名） | D19: 6万円（150名） | E19: 300名 | F19: 単位
B20: Step1 Input (画像×1500tok) [USD] | C20: =C10*単価表!C17/1000000*単価表!C5 | D20: =D10*単価表!C17/1000000*単価表!C5 | E20: =E10*単価表!C17/1000000*単価表!C5 | F20: USD/資料
B21: Step1 Output (画像×500tok) [USD] | C21: =C10*単価表!C18/1000000*単価表!D5 | D21: =D10*単価表!C18/1000000*単価表!D5 | E21: =E10*単価表!C18/1000000*単価表!D5 | F21: USD/資料
B22: Step2 Input (文字×0.5tok) [USD] | C22: =C9*単価表!C19/1000000*単価表!C6 | D22: =D9*単価表!C19/1000000*単価表!C6 | E22: =E9*単価表!C19/1000000*単価表!C6 | F22: USD/資料
B23: Step2 Output (文字×0.5tok) [USD] | C23: =C9*単価表!C19/1000000*単価表!D6 | D23: =D9*単価表!C19/1000000*単価表!D6 | E23: =E9*単価表!C19/1000000*単価表!D6 | F23: USD/資料
B24: Step3 構造提案+要約生成 [USD] | C24: =(単価表!C21+単価表!C23*C8)/1000000*単価表!C6+(単価表!C22+単価表!C24*C8)/1000000*単価表!D6 | D24: =(単価表!C21+単価表!C23*D8)/1000000*単価表!C6+(単価表!C22+単価表!C24*D8)/1000000*単価表!D6 | E24: =(単価表!C21+単価表!C23*E8)/1000000*単価表!C6+(単価表!C22+単価表!C24*E8)/1000000*単価表!D6 | F24: USD/資料
B25: 1資料あたりコスト [USD] | C25: =SUM(C20:C24) | D25: =SUM(D20:D24) | E25: =SUM(E20:E24)
B26: 1回あたりコスト [USD] | C26: =C25*C8 | D26: =D25*D8 | E26: =E25*E8
B27: 月間コスト [USD] | C27: =C26*C7 | D27: =D26*D7 | E27: =E26*E7
B28: ★ 月間コスト [円] | C28: =C27*C15 | D28: =D27*D15 | E28: =E27*E15
B31: ② インフラコスト（Azure固定費）
B32: リソース | C32: 現状（30名） | D32: 6万円（150名） | E32: 300名 | F32: プラン
B33: Azure AI Search | C33: =単価表!C11 | D33: =単価表!C11 | E33: =単価表!D11 | F33: Basic / Basic / Standard S0
B34: App Service Plan | C34: =単価表!C12 | D34: =50 | E34: =100 | F34: B1 / S1 / S2
B35: Azure SQL Database | C35: =単価表!C13 | D35: =30 | E35: =75 | F35: Basic / S1 / S2
B36: Azure OpenAI | C36: =0 | D36: =0 | E36: =0 | F36: S0 従量課金（全シナリオ共通）
B37: 月間コスト [USD] | C37: =SUM(C33:C36) | D37: =SUM(D33:D36) | E37: =SUM(E33:E36)
B38: ★ 月間コスト [円] | C38: =C37*C15 | D38: =D37*D15 | E38: =E37*E15
B41: ③ Chatbot回答コスト（従量課金）
B42: 項目 | C42: 現状（30名） | D42: 6万円（150名） | E42: 300名 | F42: 単位
B43: 月間質問数 | C43: =C11*C12*C13 | D43: =D11*D12*D13 | E43: =E11*E12*E13 | F43: 件/月
B44: gpt-5-mini Input [USD] | C44: =C43*単価表!C27*C14/1000000*単価表!C5 | D44: =D43*単価表!C27*D14/1000000*単価表!C5 | E44: =E43*単価表!C27*E14/1000000*単価表!C5
B45: gpt-5-mini Output [USD] | C45: =C43*単価表!C28/1000000*単価表!D5 | D45: =D43*単価表!C28/1000000*単価表!D5 | E45: =E43*単価表!C28/1000000*単価表!D5
B46: Embedding [USD] | C46: =C43*単価表!C29*C14/1000000*単価表!C7 | D46: =D43*単価表!C29*D14/1000000*単価表!C7 | E46: =E43*単価表!C29*E14/1000000*単価表!C7
B47: 月間コスト [USD] | C47: =SUM(C44:C46) | D47: =SUM(D44:D46) | E47: =SUM(E44:E46)
...
