Workbook

Sheet サマリ
A1: ■ナレッジボット利用コスト
A2: コスト区分 | B2: 月額(円) | C2: 計算式
A3: ① ナレッジ更新コスト | B3: 1,617~5,659 | C3: データソース数×更新コスト×更新回数（週1回で月4回） 4つ×100-350円×月4回=1,617~5,659円 ⇒更新差分の量に応じてコストは変動想定
A4: ② インフラコスト | B4: 13635 | C4: 30人程度が利用する構成。検索エンジン（Azure AI Search）、サーバー（App Service Plan）、データベース（Azure SQL Database）をいずれもBasic想定 ※50-200人規模で利用する場合はサーバー・データベースはStandardプランに変更し+10,000円程度が発生
A5: ③ Chatbot回答コスト | B5: 4989.545 | C5: 利用者数×質問回数×稼働日×1QAあたりの費用で試算 30人×20回×22営業×0.38円 = 4,989.5円
A7: ■料金・契約チームに限定した場合のコスト合計
A8: 月額合計 | B8: 20,241円 ~ 24,283円
A9: 年間合計 | B9: 242,892円~291,396円
A11: ■EC全体に拡大した場合の超概算
A12: インフラ＋1万、回答コストが150名ほどで約5倍の2.5万円と仮定すると
A13: 月額合計 | B13: 5~5.5万程度
A14: 年間合計 | B14: 60~67万程度

Sheet 計算
B1: EC業務ナレッジ チャットボット 月額コスト試算
B2: ※ 黄色セルの数値を変更すると自動再計算されます
B4: ■ 主要変数
B5: 項目 | C5: 値 | D5: 単位 | E5: 説明
B6: ナレッジ更新回数/月 | C6: 4 | D6: 回/月 | E6: 週次=4, 月次=1
B7: 1回あたり処理資料数 | C7: 4 | D7: 件 | E7: KMに投入する資料数
B8: 1資料あたり平均文字数 | C8: 350000 | D8: 字 | E8: 元資料のテキスト量
B9: 1資料あたり平均画像数 | C9: 250 | D9: 枚 | E9: Excel/PDF内の画像・表・図
B10: 1日あたりチャット質問数 | C10: 20 | D10: 件/日 | E10: 料金T25+契約T25想定
B11: 利用者数 | C11: 30 | D11: 人 | E11: 料金T・契約Tの平均稼働人数
B12: 月間営業日 | C12: 22 | D12: 日 | E12: 4週28日間のうち週末は計8日間あるが稼働数が縮小するとして2日分で計上
B13: Agent平均検索ラウンド数 | C13: 1.5 | D13: 回 | E13: FC1回+追加0.5回
B14: 為替レート (USD→JPY) | C14: 150 | D14: 円/USD
B17: ① ナレッジ更新コスト（Knowledge Maker API費用）
B18: 項目 | C18: 計算式 | D18: 数量 | E18: コスト(USD)
B19: Step1: 文字起こし (gpt-5-mini Vision)
B20: Input (画像×1500tok) | C20: 画像数 × 1500 × $0.25/1M | D20: =C9*1500 -> 375000 | E20: =C9*1500/1000000*単価表!C3 -> 0.09375
B21: Output (画像×500tok) | C21: 画像数 × 500 × $2.00/1M | D21: =C9*500 -> 125000 | E21: =C9*500/1000000*単価表!D3 -> 0.25
B22: Step2: 綺麗化 (gpt-5.1)
B23: Input (文字数×0.5tok) | C23: 文字数 × 0.5 × $1.25/1M | D23: =C8*0.5 -> 175000 | E23: =C8*0.5/1000000*単価表!C4 -> 0.21875
B24: Output (≒Input同量) | C24: 文字数 × 0.5 × $10.00/1M | D24: =C8*0.5 -> 175000 | E24: =C8*0.5/1000000*単価表!D4 -> 1.75
B25: Step3: デプロイ (gpt-5.1)
B26: 構造提案 + 要約生成 | C26: (10K+2K×資料数)in + (8K+2K×資料数)out | D26: =(10000+2000*C7)+(8000+2000*C7) -> 34000 | E26: =(10000+2000*C7)/1000000*単価表!C4+(8000+2000*C7)/1000000*単価表!D4 -> 0.1825
B28: 1資料あたりコスト (USD) | E28: =E20+E21+E23+E24+E26/C7 -> 2.358125
B29: 1回あたりコスト (USD) | E29: =E28*C7 -> 9.4325
B30: 月間コスト (USD) | E30: =E29*C6 -> 37.73
B31: ★ 月間コスト (JPY) | E31: =E30*C14 -> 5659.5
B34: ② インフラコスト（Azure固定費）
B35: リソース | C35: プラン | D35: 月額(USD) | E35: 月額(JPY)
B36: Azure AI Search | C36: Basic | D36: =単価表!C9 -> 73 | E36: =D36*C14 -> 10950
B37: App Service Plan | C37: B1 | D37: =単価表!C10 -> 13 | E37: =D37*C14 -> 1950
B38: Azure SQL Database | C38: Basic 5DTU | D38: =単価表!C11 -> 4.9 | E38: =D38*C14 -> 735
B39: Azure OpenAI* | C39: S0 (従量課金) | D39: 0 | E39: =D39*C14 -> 0
B40: ★ 月間コスト (JPY) | D40: =SUM(D36:D39) -> 90.9 | E40: =D40*C14 -> 13635
B41: *Azure OpenAIは従量課金のため、API維持のインフラコストはかからない。従量課金分は以下のチャットボットの回答コストにて計上。
B43: ③ Chatbot回答コスト（従量課金）
B44: 項目 | C44: 計算式 | D44: 月間利用数/トークン数 | E44: コスト(USD)
B45: 月間質問数 | C45: 日あたり質問数×利用者数×営業日 | D45: =C10*C12*C11 -> 13200
B46: gpt-5-mini Input | C46: 質問数 × 4000tok × ラウンド数 | D46: =D45*4000*C13 -> 79200000 | E46: =D46/1000000*単価表!C3 -> 19.8
B47: gpt-5-mini Output | C47: 質問数 × 500tok | D47: =D45*500 -> 6600000 | E47: =D47/1000000*単価表!D3 -> 13.2
...

Sheet 単価表
B1: 単価表・参照データ（2026年2月時点）
B2: モデル名 | C2: Input ($/1Mトークン) | D2: Output ($/1Mトークン)
B3: gpt-5-mini | C3: 0.25 | D3: 2
B4: gpt-5.1 | C4: 1.25 | D4: 10
B5: text-embedding-3-large | C5: 0.13 | D5: —
B7: ■ Azure 固定費（月額）
B8: リソース | C8: 月額 (USD) | D8: プラン
B9: Azure AI Search | C9: 73 | D9: Basic
B10: App Service Plan | C10: 13 | D10: B1
B11: Azure SQL Database | C11: 4.9 | D11: Basic 5DTU
B13: ■ Knowledge Maker 処理パラメータ
B14: パラメータ | C14: 値 | D14: 備考
B15: 1画像あたり Input トークン | C15: 1500 | D15: Vision API prompt + image
B16: 1画像あたり Output トークン | C16: 500 | D16: 画像説明テキスト
B17: 日本語 文字→トークン 変換係数 | C17: 0.5 | D17: 1文字 ≒ 0.5トークン
B18: Step2 テンプレートトークン | C18: 2000 | D18: フォーマット指示
B19: Step3 構造提案 Input トークン | C19: 10000 | D19: 全資料要約を含む
B20: Step3 構造提案 Output トークン | C20: 8000 | D20: フォルダ構造JSON
B21: Step3 要約 Input トークン/ファイル | C21: 2000
B22: Step3 要約 Output トークン/ファイル | C22: 2000
B24: ■ Chat 処理パラメータ
B25: パラメータ | C25: 値 | D25: 備考
B26: 1質問あたり Input トークン | C26: 4000 | D26: システムプロンプト + 検索結果20件
B27: 1質問あたり Output トークン | C27: 500 | D27: 回答テキスト
B28: Embedding クエリトークン/質問 | C28: 100 | D28: 質問文のベクトル化
B30: ■ 現在のchatbot実績値（参考）
B31: 項目 | C31: 値 | D31: 備考
B32: 登録ナレッジ数 | C32: 54本 | D32: 5つの元資料から分割
B33: チャンク総数 | C33: 1,538件 | D33: ####見出し単位で分割
B34: 総文字数（変換後MD） | C34: 1,285,439字 | D34: 約128万文字
B35: 画像参照数 | C35: 1,086件 | D35: AI-OCRでテキスト化済み
B36: 元資料数 | C36: 5件 | D36: 契約T手順書/料金T業務/他3件
B37: 検索精度 | C37: 100% | D37: 20問テスト
B38: E2Eレイテンシ | C38: 18.5秒 | D38: LLM推論87%占有
B41: ■ 元資料（inputファイル）の内訳
B42: 元資料名 | C42: 生成MD数 | D42: 変換後文字数 | E42: 画像参照数
B43: 契約T手順書 | C43: 27本 | D43: ~387,000字 | E43: ~277枚
B44: 【料金Ｔ】業務 | C44: 24本 | D44: ~345,000字 | E44: ~249枚
B45: コンシェルジュ業務一覧表 | C45: 1本 | D45: ~3,000字 | E45: 0枚
B46: 【EC】料金Tからのお知らせ | C46: 1本 | D46: ~467,000字 | E46: ~515枚
...
